<?xml version="1.0"?>
<robot name="arm" xmlns:xacro="http://ros.org/wiki/xacro">
  <link name="base_link">
  </link>
  <joint name="m1" type="continuous">
    <parent link="base_link"/>
    <child link="c1"/>
    <axis xyz="8.553496e-07 -7.256564e-08 1"/>
    <limit effort="10000" velocity="10"/>
    <origin xyz="0.22294 -0.3233 0.15621" rpy="1.5708014 -1.212808 -2.1141561e-06"/>
  </joint>
  <link name="c1">
  </link>
  <joint name="m2" type="continuous">
    <parent link="c1"/>
    <child link="c2"/>
    <axis xyz="-2.5285115e-07 -6.7793115e-07 1"/>
    <limit effort="10000" velocity="10"/>
    <origin xyz="-0.15 0 0.16" rpy="1.5707989 1.1749994 3.1415846"/>
  </joint>
  <link name="c2">
  </link>
  <joint name="m3" type="continuous">
    <parent link="c2"/>
    <child link="c3"/>
    <axis xyz="2.8437628e-07 1 -5.379857e-07"/>
    <limit effort="10000" velocity="10"/>
    <origin xyz="-0.35 0 0" rpy="-1.5707994 4.5196361e-07 1.0292908"/>
  </joint>
  <link name="c3">
  </link>
  <joint name="m4" type="continuous">
    <parent link="c3"/>
    <child link="c4"/>
    <axis xyz="1 -4.230667e-07 -3.6351955e-07"/>
    <limit effort="10000" velocity="10"/>
    <origin xyz="0.18049 0.0355 0.045291" rpy="2.4013011 -1.6983488e-08 -3.1415863"/>
  </joint>
  <link name="c4">
  </link>
  <joint name="m5" type="continuous">
    <parent link="c4"/>
    <child link="c5"/>
    <axis xyz="1 -0.0019923442 -1.31721265e-08"/>
    <limit effort="10000" velocity="10"/>
    <origin xyz="-0.17922 0.075288 0" rpy="-3.0324 0.00021713064 -1.5727998"/>
  </joint>
  <link name="c5">
  </link>
</robot>
