<?xml version="1.0" encoding="utf-8"?>
<!-- This URDF was automatically created by SolidWorks to URDF Exporter! Originally created by Stephen Brawner (brawner@gmail.com) 
     Commit Version: 1.6.0-1-g15f4949  Build Version: 1.6.7594.29634
     For more information, please see http://wiki.ros.org/sw_urdf_exporter -->
<robot
  name="asseyrot">
  <link
    name="baselink">
    <inertial>
      <origin
        xyz="-0.069094 0.10314 0.017969"
        rpy="0 0 0" />
      <mass
        value="0.84715" />
      <inertia
        ixx="0.0084618"
        ixy="3.5834E-34"
        ixz="-1.2042E-18"
        iyy="0.0084618"
        iyz="-8.6308E-35"
        izz="0.016321" />
    </inertial>
    <visual>
      <origin
        xyz="0 0 0"
        rpy="0 0 0" />
      <geometry>
        <mesh
          filename="package://asseyrot/meshes/baselink.STL" />
      </geometry>
      <material
        name="">
        <color
          rgba="0.2 0.7 0.3 1" />
      </material>
    </visual>
    <collision>
      <origin
        xyz="0 0 0"
        rpy="0 0 0" />
      <geometry>
        <mesh
          filename="package://asseyrot/meshes/base_link.STL" />
      </geometry>
    </collision>
  </link>
  <link
    name="r1">
    <inertial>
      <origin
        xyz="-3.4694E-17 5.5511E-16 0.0075165"
        rpy="0 0 0" />
      <mass
        value="1.2687" />
      <inertia
        ixx="0.0066866"
        ixy="2.6021E-18"
        ixz="-1.998E-21"
        iyy="0.0066866"
        iyz="3.767E-20"
        izz="0.013319" />
    </inertial>
    <visual>
      <origin
        xyz="0 0 0"
        rpy="0 0 0" />
      <geometry>
        <mesh
          filename="package://asseyrot/meshes/r1.STL" />
      </geometry>
      <material
        name="">
        <color
          rgba="0.2 0.4 0.7 1" />
      </material>
    </visual>
    <collision>
      <origin
        xyz="0 0 0"
        rpy="0 0 0" />
      <geometry>
        <mesh
          filename="package://asseyrot/meshes/r1.STL" />
      </geometry>
    </collision>
  </link>
  <joint
    name="mtr1"
    type="continuous">
    <origin
      xyz="-0.069094 0.10314 0.06"
      rpy="0 0 0.32037" />
    <parent
      link="baselink" />
    <child
      link="r1" />
    <axis
      xyz="0 0 1" />
  </joint>
  <joint
  	name="asdf"
  	type="fixed">
  	<origin
      xyz="-0.069094 -1.10314 0.06"
      rpy="0 0 0.32037" />
    <parent
      link="base_link" />
    <child
      link="baselink" />
    <axis
      xyz="0 0 1" />
  </joint>
</robot>