<?xml version="1.0"?>
<robot name="assy_6j" xmlns:xacro="http://ros.org/wiki/xacro">
  <link name="base_link">
  </link>
  <joint name="m1" type="continuous">
    <parent link="base_link"/>
    <child link="c1"/>
    <axis xyz="0 0 1"/>
    <limit effort="10000" velocity="10"/>
    <origin xyz="0 0 0.084" rpy="0 0 -0.35800585"/>
  </joint>
  <link name="c1">
  </link>
  <joint name="m2" type="continuous">
    <parent link="c1"/>
    <child link="c2"/>
    <axis xyz="-2.5285115e-07 -6.7793115e-07 1"/>
    <limit effort="10000" velocity="10"/>
    <origin xyz="-0.15 0 0.16" rpy="1.5707989 1.1750016 3.1415846"/>
  </joint>
  <link name="c2">
  </link>
  <joint name="m3" type="continuous">
    <parent link="c2"/>
    <child link="c3"/>
    <axis xyz="2.8437628e-07 1 -5.379857e-07"/>
    <limit effort="10000" velocity="10"/>
    <origin xyz="-0.35 0 0" rpy="-1.5707994 4.5195597e-07 1.0292888"/>
  </joint>
  <link name="c3">
  </link>
  <joint name="m4" type="continuous">
    <parent link="c3"/>
    <child link="c4"/>
    <axis xyz="1 -4.230667e-07 -3.6351955e-07"/>
    <limit effort="10000" velocity="10"/>
    <origin xyz="0.18049 0.0355 0.045291" rpy="2.4012997 -1.6984385e-08 -3.1415863"/>
  </joint>
  <link name="c4">
  </link>
  <joint name="m5" type="continuous">
    <parent link="c4"/>
    <child link="c5"/>
    <axis xyz="1 1.453129e-07 -2.25992e-07"/>
    <limit effort="10000" velocity="10"/>
    <origin xyz="-0.17922 0 0" rpy="-1.4615992 -1.6907606e-07 -1.5708001"/>
  </joint>
  <link name="c5">
  </link>
  <joint name="m6" type="continuous">
    <parent link="c5"/>
    <child link="c6"/>
    <axis xyz="4.3015445e-09 3.1880762e-07 1"/>
    <limit effort="10000" velocity="10"/>
    <origin xyz="0 -0.13847 0" rpy="-1.5708001 0.0019920038 -3.6664725e-09"/>
  </joint>
  <link name="c6">
  </link>
</robot>
